<?xml version="1.0"?>
<robot name="spherical_actuators">

  <!-- Model 0 -->
  <link name="intermediate_x_0"/>
  <link name="intermediate_y_0"/>
  <link name="sphere_0">
    <inertial>
      <origin xyz="0 0 0" rpy="0 0 0"/>
      <mass value="0.1"/>
      <inertia ixx="2e-5" ixy="0" ixz="0" iyy="2e-5" iyz="0" izz="2e-5"/>
    </inertial>

    <visual>
      <origin xyz="0 0 0" rpy="0 0 0"/>
      <geometry>
        <sphere radius="0.01"/>
      </geometry>
      <material name="purple">
        <color rgba="0.4 0 1 1"/>
      </material>
    </visual>

    <collision>
      <origin xyz="0 0 0" rpy="0 0 0"/>
      <geometry>
        <sphere radius="0.01"/>
      </geometry>
    </collision>
  </link>

  <!-- Joints for Model 0 -->
  <joint name="prismatic_x_0" type="prismatic">
    <parent link="world"/>
    <child link="intermediate_x_0"/>
    <origin xyz="0.0 0 0" rpy="0 0 0"/>
    <axis xyz="1 0 0"/>
    <limit lower="0" upper="1" effort="1000" velocity="1"/>
  </joint>

  <joint name="prismatic_y_0" type="prismatic">
    <parent link="intermediate_x_0"/>
    <child link="intermediate_y_0"/>
    <origin xyz="0 0 0" rpy="0 0 0"/>
    <axis xyz="0 1 0"/>
    <limit lower="0" upper="1" effort="1000" velocity="1"/>
  </joint>

  <joint name="prismatic_z_0" type="prismatic">
    <parent link="intermediate_y_0"/>
    <child link="sphere_0"/>
    <origin xyz="0 0 0" rpy="0 0 0"/>
    <axis xyz="0 0 1"/>
    <limit lower="0" upper="1" effort="1000" velocity="1"/>
  </joint>

  <!-- Model 1 -->
  <link name="intermediate_x_1"/>
  <link name="intermediate_y_1"/>
  <link name="sphere_1">
    <inertial>
      <origin xyz="0 0 0" rpy="0 0 0"/>
      <mass value="0.1"/>
      <inertia ixx="2e-5" ixy="0" ixz="0" iyy="2e-5" iyz="0" izz="2e-5"/>
    </inertial>

    <visual>
      <origin xyz="0 0 0" rpy="0 0 0"/>
      <geometry>
        <sphere radius="0.01"/>
      </geometry>
      <material name="purple">
        <color rgba="0.4 0 1 1"/>
      </material>
    </visual>

    <collision>
      <origin xyz="0 0 0" rpy="0 0 0"/>
      <geometry>
        <sphere radius="0.01"/>
      </geometry>
    </collision>
  </link>

  <!-- Joints for Model 1 -->
  <joint name="prismatic_x_1" type="prismatic">
    <parent link="world"/>
    <child link="intermediate_x_1"/>
    <origin xyz="0.1 0 0" rpy="0 0 0"/>
    <axis xyz="1 0 0"/>
    <limit lower="0" upper="1" effort="1000" velocity="1"/>
  </joint>

  <joint name="prismatic_y_1" type="prismatic">
    <parent link="intermediate_x_1"/>
    <child link="intermediate_y_1"/>
    <origin xyz="0 0 0" rpy="0 0 0"/>
    <axis xyz="0 1 0"/>
    <limit lower="0" upper="1" effort="1000" velocity="1"/>
  </joint>

  <joint name="prismatic_z_1" type="prismatic">
    <parent link="intermediate_y_1"/>
    <child link="sphere_1"/>
    <origin xyz="0 0 0" rpy="0 0 0"/>
    <axis xyz="0 0 1"/>
    <limit lower="0" upper="1" effort="1000" velocity="1"/>
  </joint>

  <!-- Model 2 -->
  <link name="intermediate_x_2"/>
  <link name="intermediate_y_2"/>
  <link name="sphere_2">
    <inertial>
      <origin xyz="0 0 0" rpy="0 0 0"/>
      <mass value="0.1"/>
      <inertia ixx="2e-5" ixy="0" ixz="0" iyy="2e-5" iyz="0" izz="2e-5"/>
    </inertial>

    <visual>
      <origin xyz="0 0 0" rpy="0 0 0"/>
      <geometry>
        <sphere radius="0.01"/>
      </geometry>
      <material name="purple">
        <color rgba="0.4 0 1 1"/>
      </material>
    </visual>

    <collision>
      <origin xyz="0 0 0" rpy="0 0 0"/>
      <geometry>
        <sphere radius="0.01"/>
      </geometry>
    </collision>
  </link>

  <!-- Joints for Model 2 -->
  <joint name="prismatic_x_2" type="prismatic">
    <parent link="world"/>
    <child link="intermediate_x_2"/>
    <origin xyz="0.2 0 0" rpy="0 0 0"/>
    <axis xyz="1 0 0"/>
    <limit lower="0" upper="1" effort="1000" velocity="1"/>
  </joint>

  <joint name="prismatic_y_2" type="prismatic">
    <parent link="intermediate_x_2"/>
    <child link="intermediate_y_2"/>
    <origin xyz="0 0 0" rpy="0 0 0"/>
    <axis xyz="0 1 0"/>
    <limit lower="0" upper="1" effort="1000" velocity="1"/>
  </joint>

  <joint name="prismatic_z_2" type="prismatic">
    <parent link="intermediate_y_2"/>
    <child link="sphere_2"/>
    <origin xyz="0 0 0" rpy="0 0 0"/>
    <axis xyz="0 0 1"/>
    <limit lower="0" upper="1" effort="1000" velocity="1"/>
  </joint>

  <!-- Model 3 -->
  <link name="intermediate_x_3"/>
  <link name="intermediate_y_3"/>
  <link name="sphere_3">
    <inertial>
      <origin xyz="0 0 0" rpy="0 0 0"/>
      <mass value="0.1"/>
      <inertia ixx="2e-5" ixy="0" ixz="0" iyy="2e-5" iyz="0" izz="2e-5"/>
    </inertial>

    <visual>
      <origin xyz="0 0 0" rpy="0 0 0"/>
      <geometry>
        <sphere radius="0.01"/>
      </geometry>
      <material name="purple">
        <color rgba="0.4 0 1 1"/>
      </material>
    </visual>

    <collision>
      <origin xyz="0 0 0" rpy="0 0 0"/>
      <geometry>
        <sphere radius="0.01"/>
      </geometry>
    </collision>
  </link>

  <!-- Joints for Model 3 -->
  <joint name="prismatic_x_3" type="prismatic">
    <parent link="world"/>
    <child link="intermediate_x_3"/>
    <origin xyz="0.30000000000000004 0 0" rpy="0 0 0"/>
    <axis xyz="1 0 0"/>
    <limit lower="0" upper="1" effort="1000" velocity="1"/>
  </joint>

  <joint name="prismatic_y_3" type="prismatic">
    <parent link="intermediate_x_3"/>
    <child link="intermediate_y_3"/>
    <origin xyz="0 0 0" rpy="0 0 0"/>
    <axis xyz="0 1 0"/>
    <limit lower="0" upper="1" effort="1000" velocity="1"/>
  </joint>

  <joint name="prismatic_z_3" type="prismatic">
    <parent link="intermediate_y_3"/>
    <child link="sphere_3"/>
    <origin xyz="0 0 0" rpy="0 0 0"/>
    <axis xyz="0 0 1"/>
    <limit lower="0" upper="1" effort="1000" velocity="1"/>
  </joint>

  <!-- Model 4 -->
  <link name="intermediate_x_4"/>
  <link name="intermediate_y_4"/>
  <link name="sphere_4">
    <inertial>
      <origin xyz="0 0 0" rpy="0 0 0"/>
      <mass value="0.1"/>
      <inertia ixx="2e-5" ixy="0" ixz="0" iyy="2e-5" iyz="0" izz="2e-5"/>
    </inertial>

    <visual>
      <origin xyz="0 0 0" rpy="0 0 0"/>
      <geometry>
        <sphere radius="0.01"/>
      </geometry>
      <material name="purple">
        <color rgba="0.4 0 1 1"/>
      </material>
    </visual>

    <collision>
      <origin xyz="0 0 0" rpy="0 0 0"/>
      <geometry>
        <sphere radius="0.01"/>
      </geometry>
    </collision>
  </link>

  <!-- Joints for Model 4 -->
  <joint name="prismatic_x_4" type="prismatic">
    <parent link="world"/>
    <child link="intermediate_x_4"/>
    <origin xyz="0.4 0 0" rpy="0 0 0"/>
    <axis xyz="1 0 0"/>
    <limit lower="0" upper="1" effort="1000" velocity="1"/>
  </joint>

  <joint name="prismatic_y_4" type="prismatic">
    <parent link="intermediate_x_4"/>
    <child link="intermediate_y_4"/>
    <origin xyz="0 0 0" rpy="0 0 0"/>
    <axis xyz="0 1 0"/>
    <limit lower="0" upper="1" effort="1000" velocity="1"/>
  </joint>

  <joint name="prismatic_z_4" type="prismatic">
    <parent link="intermediate_y_4"/>
    <child link="sphere_4"/>
    <origin xyz="0 0 0" rpy="0 0 0"/>
    <axis xyz="0 0 1"/>
    <limit lower="0" upper="1" effort="1000" velocity="1"/>
  </joint>

  <!-- Model 5 -->
  <link name="intermediate_x_5"/>
  <link name="intermediate_y_5"/>
  <link name="sphere_5">
    <inertial>
      <origin xyz="0 0 0" rpy="0 0 0"/>
      <mass value="0.1"/>
      <inertia ixx="2e-5" ixy="0" ixz="0" iyy="2e-5" iyz="0" izz="2e-5"/>
    </inertial>

    <visual>
      <origin xyz="0 0 0" rpy="0 0 0"/>
      <geometry>
        <sphere radius="0.01"/>
      </geometry>
      <material name="purple">
        <color rgba="0.4 0 1 1"/>
      </material>
    </visual>

    <collision>
      <origin xyz="0 0 0" rpy="0 0 0"/>
      <geometry>
        <sphere radius="0.01"/>
      </geometry>
    </collision>
  </link>

  <!-- Joints for Model 5 -->
  <joint name="prismatic_x_5" type="prismatic">
    <parent link="world"/>
    <child link="intermediate_x_5"/>
    <origin xyz="0.5 0 0" rpy="0 0 0"/>
    <axis xyz="1 0 0"/>
    <limit lower="0" upper="1" effort="1000" velocity="1"/>
  </joint>

  <joint name="prismatic_y_5" type="prismatic">
    <parent link="intermediate_x_5"/>
    <child link="intermediate_y_5"/>
    <origin xyz="0 0 0" rpy="0 0 0"/>
    <axis xyz="0 1 0"/>
    <limit lower="0" upper="1" effort="1000" velocity="1"/>
  </joint>

  <joint name="prismatic_z_5" type="prismatic">
    <parent link="intermediate_y_5"/>
    <child link="sphere_5"/>
    <origin xyz="0 0 0" rpy="0 0 0"/>
    <axis xyz="0 0 1"/>
    <limit lower="0" upper="1" effort="1000" velocity="1"/>
  </joint>

  <!-- Model 6 -->
  <link name="intermediate_x_6"/>
  <link name="intermediate_y_6"/>
  <link name="sphere_6">
    <inertial>
      <origin xyz="0 0 0" rpy="0 0 0"/>
      <mass value="0.1"/>
      <inertia ixx="2e-5" ixy="0" ixz="0" iyy="2e-5" iyz="0" izz="2e-5"/>
    </inertial>

    <visual>
      <origin xyz="0 0 0" rpy="0 0 0"/>
      <geometry>
        <sphere radius="0.01"/>
      </geometry>
      <material name="purple">
        <color rgba="0.4 0 1 1"/>
      </material>
    </visual>

    <collision>
      <origin xyz="0 0 0" rpy="0 0 0"/>
      <geometry>
        <sphere radius="0.01"/>
      </geometry>
    </collision>
  </link>

  <!-- Joints for Model 6 -->
  <joint name="prismatic_x_6" type="prismatic">
    <parent link="world"/>
    <child link="intermediate_x_6"/>
    <origin xyz="0.6000000000000001 0 0" rpy="0 0 0"/>
    <axis xyz="1 0 0"/>
    <limit lower="0" upper="1" effort="1000" velocity="1"/>
  </joint>

  <joint name="prismatic_y_6" type="prismatic">
    <parent link="intermediate_x_6"/>
    <child link="intermediate_y_6"/>
    <origin xyz="0 0 0" rpy="0 0 0"/>
    <axis xyz="0 1 0"/>
    <limit lower="0" upper="1" effort="1000" velocity="1"/>
  </joint>

  <joint name="prismatic_z_6" type="prismatic">
    <parent link="intermediate_y_6"/>
    <child link="sphere_6"/>
    <origin xyz="0 0 0" rpy="0 0 0"/>
    <axis xyz="0 0 1"/>
    <limit lower="0" upper="1" effort="1000" velocity="1"/>
  </joint>

  <!-- Model 7 -->
  <link name="intermediate_x_7"/>
  <link name="intermediate_y_7"/>
  <link name="sphere_7">
    <inertial>
      <origin xyz="0 0 0" rpy="0 0 0"/>
      <mass value="0.1"/>
      <inertia ixx="2e-5" ixy="0" ixz="0" iyy="2e-5" iyz="0" izz="2e-5"/>
    </inertial>

    <visual>
      <origin xyz="0 0 0" rpy="0 0 0"/>
      <geometry>
        <sphere radius="0.01"/>
      </geometry>
      <material name="purple">
        <color rgba="0.4 0 1 1"/>
      </material>
    </visual>

    <collision>
      <origin xyz="0 0 0" rpy="0 0 0"/>
      <geometry>
        <sphere radius="0.01"/>
      </geometry>
    </collision>
  </link>

  <!-- Joints for Model 7 -->
  <joint name="prismatic_x_7" type="prismatic">
    <parent link="world"/>
    <child link="intermediate_x_7"/>
    <origin xyz="0.7000000000000001 0 0" rpy="0 0 0"/>
    <axis xyz="1 0 0"/>
    <limit lower="0" upper="1" effort="1000" velocity="1"/>
  </joint>

  <joint name="prismatic_y_7" type="prismatic">
    <parent link="intermediate_x_7"/>
    <child link="intermediate_y_7"/>
    <origin xyz="0 0 0" rpy="0 0 0"/>
    <axis xyz="0 1 0"/>
    <limit lower="0" upper="1" effort="1000" velocity="1"/>
  </joint>

  <joint name="prismatic_z_7" type="prismatic">
    <parent link="intermediate_y_7"/>
    <child link="sphere_7"/>
    <origin xyz="0 0 0" rpy="0 0 0"/>
    <axis xyz="0 0 1"/>
    <limit lower="0" upper="1" effort="1000" velocity="1"/>
  </joint>

  <!-- Model 8 -->
  <link name="intermediate_x_8"/>
  <link name="intermediate_y_8"/>
  <link name="sphere_8">
    <inertial>
      <origin xyz="0 0 0" rpy="0 0 0"/>
      <mass value="0.1"/>
      <inertia ixx="2e-5" ixy="0" ixz="0" iyy="2e-5" iyz="0" izz="2e-5"/>
    </inertial>

    <visual>
      <origin xyz="0 0 0" rpy="0 0 0"/>
      <geometry>
        <sphere radius="0.01"/>
      </geometry>
      <material name="purple">
        <color rgba="0.4 0 1 1"/>
      </material>
    </visual>

    <collision>
      <origin xyz="0 0 0" rpy="0 0 0"/>
      <geometry>
        <sphere radius="0.01"/>
      </geometry>
    </collision>
  </link>

  <!-- Joints for Model 8 -->
  <joint name="prismatic_x_8" type="prismatic">
    <parent link="world"/>
    <child link="intermediate_x_8"/>
    <origin xyz="0.8 0 0" rpy="0 0 0"/>
    <axis xyz="1 0 0"/>
    <limit lower="0" upper="1" effort="1000" velocity="1"/>
  </joint>

  <joint name="prismatic_y_8" type="prismatic">
    <parent link="intermediate_x_8"/>
    <child link="intermediate_y_8"/>
    <origin xyz="0 0 0" rpy="0 0 0"/>
    <axis xyz="0 1 0"/>
    <limit lower="0" upper="1" effort="1000" velocity="1"/>
  </joint>

  <joint name="prismatic_z_8" type="prismatic">
    <parent link="intermediate_y_8"/>
    <child link="sphere_8"/>
    <origin xyz="0 0 0" rpy="0 0 0"/>
    <axis xyz="0 0 1"/>
    <limit lower="0" upper="1" effort="1000" velocity="1"/>
  </joint>

  <!-- Model 9 -->
  <link name="intermediate_x_9"/>
  <link name="intermediate_y_9"/>
  <link name="sphere_9">
    <inertial>
      <origin xyz="0 0 0" rpy="0 0 0"/>
      <mass value="0.1"/>
      <inertia ixx="2e-5" ixy="0" ixz="0" iyy="2e-5" iyz="0" izz="2e-5"/>
    </inertial>

    <visual>
      <origin xyz="0 0 0" rpy="0 0 0"/>
      <geometry>
        <sphere radius="0.01"/>
      </geometry>
      <material name="purple">
        <color rgba="0.4 0 1 1"/>
      </material>
    </visual>

    <collision>
      <origin xyz="0 0 0" rpy="0 0 0"/>
      <geometry>
        <sphere radius="0.01"/>
      </geometry>
    </collision>
  </link>

  <!-- Joints for Model 9 -->
  <joint name="prismatic_x_9" type="prismatic">
    <parent link="world"/>
    <child link="intermediate_x_9"/>
    <origin xyz="0.9 0 0" rpy="0 0 0"/>
    <axis xyz="1 0 0"/>
    <limit lower="0" upper="1" effort="1000" velocity="1"/>
  </joint>

  <joint name="prismatic_y_9" type="prismatic">
    <parent link="intermediate_x_9"/>
    <child link="intermediate_y_9"/>
    <origin xyz="0 0 0" rpy="0 0 0"/>
    <axis xyz="0 1 0"/>
    <limit lower="0" upper="1" effort="1000" velocity="1"/>
  </joint>

  <joint name="prismatic_z_9" type="prismatic">
    <parent link="intermediate_y_9"/>
    <child link="sphere_9"/>
    <origin xyz="0 0 0" rpy="0 0 0"/>
    <axis xyz="0 0 1"/>
    <limit lower="0" upper="1" effort="1000" velocity="1"/>
  </joint>
</robot>